Workbook

Sheet Cover
A1: Alphabet Inc. (GOOG/GOOGL)
A2: Segment-Driven DCF Model | v5 | 2026-02-10
A4: 数据来源 Data Sources | B4: Alphabet 2025 10-K + Q4'25 Earnings Call + FRED
A5: CapEx 2026 指引 | B5: $75B/quarter → annualized ~$180B (earnings call 2026-02-04)
A6: 模型特色 Key Feature | B6: 11-Tab model: 三表联动 (PL + BS + CF) + Segment P&L 交叉验证
B7: Dual-layer P&L: Segment_PL (by division) + Consolidated_PL (by cost type)
A9: 使用步骤 HOW TO USE
A10: Step 1 | B10: Go to Assumptions → edit BLUE cells only (蓝底单元格)
A11: Step 2 | B11: Switch scenario: Assumptions!B2 → Base / Bull / Bear
A12: Step 3 | B12: All tabs auto-update: Revenue → Segment PL → Consolidated PL → BS → CF → DCF
A13: Step 4 | B13: Check Segment_PL cross-check row: difference should = 0
A14: Step 5 | B14: Check BS balance check row: Total Assets = Total L&E
A15: Step 6 | B15: Every assumption shows HISTORICAL values (2023-2025) for reference
A16: Step 7 | B16: Notes column (col J) explains prediction logic for every row

Sheet Key_Summary
A1: Alphabet Inc. (GOOG) - 财务摘要 Executive Summary
A2: 单位：百万美元（USD Million）
A4: 核心财务指标 Key Financial Highlights | B4: 2023A | C4: 2024A | D4: 2025A | E4: 2026E | F4: 2027E | G4: 2028E | H4: 说明 Notes
A5: 总收入 Total Revenue | B5: =Consolidated_PL!B5 -> 307394 | C5: =Consolidated_PL!C5 -> 350018 | D5: =Consolidated_PL!D5 -> 402836 | E5: =Consolidated_PL!E5 -> 461372.98 | F5: =Consolidated_PL!F5 -> 519292.89 | G5: =Consolidated_PL!G5 -> 578808.59 | H5: 链接自Consolidated_PL
A6: YoY增速 % | C6: =C5/B5-1 -> 0.13866243 | D6: =D5/C5-1 -> 0.15090081 | E6: =E5/D5-1 -> 0.14531219 | F6: =F5/E5-1 -> 0.12553814 | G6: =G5/F5-1 -> 0.11460912
A7: 毛利润 Gross Profit | B7: =Consolidated_PL!B15 -> 174062 | C7: =Consolidated_PL!C15 -> 203712 | D7: =Consolidated_PL!D15 -> 240301 | E7: =Consolidated_PL!E15 -> 280691.66 | F7: =Consolidated_PL!F15 -> 318114.42 | G7: =Consolidated_PL!G15 -> 356798.38
A8: 毛利率 GPM % | B8: =B7/B5 -> 0.56625048 | C8: =C7/C5 -> 0.58200435 | D8: =D7/D5 -> 0.59652315 | E8: =E7/E5 -> 0.60838339 | F8: =F7/F5 -> 0.61259151 | G8: =G7/G5 -> 0.61643588
A9: 营业利润 EBIT | B9: =Consolidated_PL!B26 -> 84293 | C9: =Consolidated_PL!C26 -> 112390 | D9: =Consolidated_PL!D26 -> 129039 | E9: =Consolidated_PL!E26 -> 157314.7 | F9: =Consolidated_PL!F26 -> 177860.09 | G9: =Consolidated_PL!G26 -> 198660.54
A10: 营业利润率 OPM % | B10: =B9/B5 -> 0.2742181 | C10: =C9/C5 -> 0.32109777 | D10: =D9/D5 -> 0.32032639 | E10: =E9/E5 -> 0.34097077 | F10: =F9/F5 -> 0.34250438 | G10: =G9/G5 -> 0.3432232
A11: 净利润 Net Income | B11: =Consolidated_PL!B33 -> 73795 | C11: =Consolidated_PL!C33 -> 100118 | D11: =Consolidated_PL!D33 -> 132170 | E11: =Consolidated_PL!E33 -> 134721.2 | F11: =Consolidated_PL!F33 -> 152188.87 | G11: =Consolidated_PL!G33 -> 169868.25
A12: 净利率 NPM % | B12: =B11/B5 -> 0.24006649 | C12: =C11/C5 -> 0.28603672 | D12: =D11/D5 -> 0.32809878 | E12: =E11/E5 -> 0.29200063 | F12: =F11/F5 -> 0.29306944 | G12: =G11/G5 -> 0.29347914
A13: NI YoY % | C13: =C12/B12-1 -> 0.19148954 | D13: =D12/C12-1 -> 0.14705127 | E13: =E12/D12-1 -> -0.1100222 | F13: =F12/E12-1 -> 0.0036602945 | G13: =G12/F12-1 -> 0.0013979609
A14: 稀释EPS | B14: =Consolidated_PL!B41 -> 5.8005817 | C14: =Consolidated_PL!C41 -> 8.0435446 | D14: =Consolidated_PL!D41 -> 10.807032 | E14: =Consolidated_PL!E41 -> 11.240443 | F14: =Consolidated_PL!F41 -> 12.956995 | G14: =Consolidated_PL!G41 -> 14.757321
A16: 分部收入结构 Revenue by Segment | B16: 2023A | C16: 2024A | D16: 2025A | E16: 2026E | F16: 2027E | G16: 2028E | H16: 说明 Notes
A17: Google Services Total | B17: =Segment_Revenue!B19 -> 272543 | C17: =Segment_Revenue!C19 -> 304930 | D17: =Segment_Revenue!D19 -> 342721 | E17: =Segment_Revenue!E19 -> 383365.78 | F17: =Segment_Revenue!F19 -> 421952.96 | G17: =Segment_Revenue!G19 -> 460189.97
A18: 占比 % | B18: =B17/B5 -> 0.88662433 | C18: =C17/C5 -> 0.87118377 | D18: =D17/D5 -> 0.85077054 | E18: =E17/E5 -> 0.83092378 | F18: =F17/F5 -> 0.81255293 | G18: =G17/G5 -> 0.79506418
A19: Google Cloud | B19: =Segment_Revenue!B22 -> 33088 | C19: =Segment_Revenue!C22 -> 43229 | D19: =Segment_Revenue!D22 -> 58705 | E19: =Segment_Revenue!E22 -> 76316.5 | F19: =Segment_Revenue!F22 -> 95395.625 | G19: =Segment_Revenue!G22 -> 116382.66
A20: 占比 % | B20: =B19/B5 -> 0.10764036 | C20: =C19/C5 -> 0.12350508 | D20: =D19/D5 -> 0.14572928 | E20: =E19/E5 -> 0.16541172 | F20: =F19/F5 -> 0.18370293 | G20: =G19/G5 -> 0.2010728
A21: Other Bets | B21: =Segment_Revenue!B26 -> 1527 | C21: =Segment_Revenue!C26 -> 1648 | D21: =Segment_Revenue!D26 -> 1537 | E21: =Segment_Revenue!E26 -> 1690.7 | F21: =Segment_Revenue!F26 -> 1944.305 | G21: =Segment_Revenue!G26 -> 2235.9507
A22: 占比 % | B22: =B21/B5 -> 0.0049675661 | C22: =C21/C5 -> 0.0047083293 | D22: =D21/D5 -> 0.0038154485 | E22: =E21/E5 -> 0.0036644972 | F22: =F21/F5 -> 0.0037441395 | G22: =G21/G5 -> 0.0038630228
A24: 资产负债核心指标 Balance Sheet Highlights | B24: 2023A | C24: 2024A | D24: 2025A | E24: 2026E | F24: 2027E | G24: 2028E | H24: 说明
A25: 总资产 Total Assets | B25: =BS!B21 -> 401392 | C25: =BS!C21 -> 450256 | D25: =BS!D21 -> 595281 | E25: =BS!E21 -> 695799.56 | F25: =BS!F21 -> 818108.66 | G25: =BS!G21 -> 960560.89
A26: 股东权益 Total Equity | B26: =BS!B40 -> 283379 | C26: =BS!C40 -> 325084 | D26: =BS!D40 -> 415265 | E26: =BS!E40 -> 502818.87 | F26: =BS!F40 -> 609731.03 | G26: =BS!G40 -> 736255.23
A27: 现金及证券 Cash & Securities | B27: =BS!B8 -> 110916 | C27: =BS!C8 -> 95657 | D27: =BS!D8 -> 126843 | E27: =BS!E8 -> 51849.151 | F27: =BS!F8 -> 17844.37 | G27: =BS!G8 -> 25105.881
A28: ROE 净资产收益率 | B28: =B11/B26 -> 0.26041097 | C28: =C11/C26 -> 0.30797578 | D28: =D11/D26 -> 0.31827869 | E28: =E11/E26 -> 0.26793187 | F28: =F11/F26 -> 0.24960002 | G28: =G11/G26 -> 0.23071924 | H28: 净利润/权益
A29: ROA 总资产收益率 | B29: =B11/B25 -> 0.18384771 | C29: =C11/C25 -> 0.22235795 | D29: =D11/D25 -> 0.2220296 | E29: =E11/E25 -> 0.1936207 | F29: =F11/F25 -> 0.18602526 | G29: =G11/G25 -> 0.17684277 | H29: 净利润/总资产
A32: 关键投资亮点 Key Investment Highlights
A33: ✓ AI驱动搜索广告核心引擎，Search+YouTube贡献>65%收入
A34: ✓ Google Cloud 48% YoY增长(Q4'25)，利润率从5%→24%快速提升
A35: ✓ AI CapEx高峰投资($180B/2026)确立长期竞争壁垒
A36: ✓ 稳健股东回报：年回购~$50B + 股息$0.88/share
A37: ✓ Net cash >$80B，资产负债表极其稳健
A38: ⚠ 风险：AI CapEx回报不确定、DOJ反垄断、Cloud竞争激烈
A40: 数据图例 Data Legend:
A41: 蓝色字体 Blue Font = 财报原始数据 Hardcoded from financials
A42: 绿色字体 Green Font = 链接自其他工作表 Links from other sheets
A43: 蓝底深蓝字体 Blue Fill = 可编辑假设 Editable assumption inputs
A44: 黄底粗体 Yellow Fill = 关键输出 Key output rows
... A51: • 10Y UST yield ~4.2% (Feb 2026), Fed 2% long-term inflation target

Sheet Assumptions
A1: Assumptions & Drivers 假设与驱动
A2: Scenario 情景 | B2: Base
A4: Parameter 参数 | B4: 2023A | C4: 2024A | D4: 2025A | F4: Base | G4: Bull | H4: Bear | I4: Selected | K4: Notes / 预测逻辑
A6: WACC 加权平均资本成本参数
A7: Risk-Free Rate 无风险利率 (10Y UST) | F7: 0.042 | G7: 0.042 | H7: 0.042 | I7: =CHOOSE(MATCH($B$2,{"Base","Bull","Bear"},0),F7,G7,H7) -> 0.042 | K7: 10Y美债收益率 ~4.2% (Feb 2026)
A8: Equity Beta 权益Beta | F8: 1.05 | G8: 1 | H8: 1.1 | I8: =CHOOSE(MATCH($B$2,{"Base","Bull","Bear"},0),F8,G8,H8) -> 1.05 | K8: 参考Bloomberg/Reuters 5Y weekly beta
A9: Equity Risk Premium ERP 股权风险溢价 | F9: 0.05 | G9: 0.052 | H9: 0.048 | I9: =CHOOSE(MATCH($B$2,{"Base","Bull","Bear"},0),F9,G9,H9) -> 0.05 | K9: Damodaran 2026 ERP estimate
A10: Pre-tax Cost of Debt Kd 税前债务成本 | F10: 0.049 | G10: 0.048 | H10: 0.052 | I10: =CHOOSE(MATCH($B$2,{"Base","Bull","Bear"},0),F10,G10,H10) -> 0.049 | K10: 参考Alphabet最新债券到期收益率
A11: Effective Tax Rate 有效税率 | B11: 0.139 | C11: 0.164 | D11: 0.168 | F11: 0.17 | G11: 0.165 | H11: 0.18 | I11: =CHOOSE(MATCH($B$2,{"Base","Bull","Bear"},0),F11,G11,H11) -> 0.17 | K11: 2023-2025历史税率参考
A12: Debt / Total Capital 债务占比 | F12: 0.03 | G12: 0.025 | H12: 0.035 | I12: =CHOOSE(MATCH($B$2,{"Base","Bull","Bear"},0),F12,G12,H12) -> 0.03 | K12: Alphabet资本结构以权益为主
A13: Terminal Growth Rate g 永续增长率 | F13: 0.03 | G13: 0.033 | H13: 0.027 | I13: =CHOOSE(MATCH($B$2,{"Base","Bull","Bear"},0),F13,G13,H13) -> 0.03 | K13: 约=长期GDP增长+通胀
A15: Derived WACC 推导的WACC
A16: Ke = Rf + Beta × ERP 股权成本 | I16: =I7+I8*I9 -> 0.0945
A17: After-tax Kd 税后债务成本 | I17: =I10*(1-I11) -> 0.04067
A18: WACC 加权平均资本成本 | I18: =(1-I12)*I16+I12*I17 -> 0.0928851
A20: Valuation Bridge 估值桥接
A21: Cash & Marketable Securities 现金及有价证券 (mm) | B21: 110916 | C21: 95657 | D21: 126843 | F21: 126843 | G21: 126843 | H21: 126843 | I21: =CHOOSE(MATCH($B$2,{"Base","Bull","Bear"},0),F21,G21,H21) -> 126843 | K21: 年末现金+短期证券合计
A22: Total Debt 总债务 (mm) | B22: 12887 | C22: 10883 | D22: 46547 | F22: 46547 | G22: 46547 | H22: 46547 | I22: =CHOOSE(MATCH($B$2,{"Base","Bull","Bear"},0),F22,G22,H22) -> 46547 | K22: 短期+长期债务
A23: Diluted Shares 稀释股数 (mm) | B23: 12722 | C23: 12447 | D23: 12230 | F23: 12230 | G23: 12230 | H23: 12230 | I23: =CHOOSE(MATCH($B$2,{"Base","Bull","Bear"},0),F23,G23,H23) -> 12230 | K23: Source: 10-K p.49
A25: Revenue Growth by Segment 分部收入增长率 (Base块)
A26: Segment | B26: 2023A | C26: 2024A | D26: 2025A | F26: 2026E | G26: 2027E | H26: 2028E | I26: 2029E | J26: 2030E
A27: Google Search & other | C27: 0.13169517 | D27: 0.13351911 | F27: 0.12 | G27: 0.1 | H27: 0.09 | I27: 0.08 | J27: 0.07 | K27: 搜索广告核心引擎
A28: YouTube ads | C28: 0.14715963 | D28: 0.11674551 | F28: 0.14 | G28: 0.12 | H28: 0.1 | I28: 0.09 | J28: 0.08 | K28: AI-driven Shorts增长
A29: Google Network | C29: -0.030435616 | D29: -0.018676504 | F29: -0.02 | G29: -0.02 | H29: -0.01 | I29: -0.01 | J29: 0 | K29: 持续缩减
A30: Subs, Platforms & Devices | C30: 0.16293819 | D30: 0.19062965 | F30: 0.18 | G30: 0.15 | H30: 0.13 | I30: 0.11 | J30: 0.09 | K30: YouTube Premium/硬件增长
A31: Google Cloud | C31: 0.30648574 | D31: 0.35800042 | F31: 0.3 | G31: 0.25 | H31: 0.22 | I31: 0.18 | J31: 0.15 | K31: AI Cloud高增长引擎
A32: Other Bets | C32: 0.079240341 | D32: -0.067354369 | F32: 0.1 | G32: 0.15 | H32: 0.15 | I32: 0.15 | J32: 0.1 | K32: Waymo等前沿业务
A34: Revenue Growth - Bull Case 乐观情景
A35: Google Search & other | F35: 0.15 | G35: 0.13 | H35: 0.11 | I35: 0.1 | J35: 0.09
A36: YouTube ads | F36: 0.18 | G36: 0.15 | H36: 0.13 | I36: 0.11 | J36: 0.1
A37: Google Network | F37: -0.01 | G37: 0 | H37: 0 | I37: 0.01 | J37: 0.01
A38: Subs, Platforms & Devices | F38: 0.22 | G38: 0.18 | H38: 0.15 | I38: 0.13 | J38: 0.11
A39: Google Cloud | F39: 0.38 | G39: 0.3 | H39: 0.25 | I39: 0.2 | J39: 0.17
A40: Other Bets | F40: 0.15 | G40: 0.2 | H40: 0.2 | I40: 0.2 | J40: 0.15
A42: Revenue Growth - Bear Case 悲观情景
A43: Google Search & other | F43: 0.08 | G43: 0.07 | H43: 0.06 | I43: 0.05 | J43: 0.04
A44: YouTube ads | F44: 0.08 | G44: 0.07 | H44: 0.06 | I44: 0.05 | J44: 0.04
A45: Google Network | F45: -0.05 | G45: -0.04 | H45: -0.03 | I45: -0.03 | J45: -0.02
A46: Subs, Platforms & Devices | F46: 0.12 | G46: 0.1 | H46: 0.09 | I46: 0.08 | J46: 0.07
A47: Google Cloud | F47: 0.22 | G47: 0.18 | H47: 0.15 | I47: 0.12 | J47: 0.1
...

Sheet Segment_Revenue
A1: Revenue Build 分部收入构建 (USD mm)
A2: 单位：百万美元 | Cloud Q4'25 = $17.7B (48% YoY)
B4: 2023 | C4: 2024 | D4: 2025 | E4: 2026E | F4: 2027E | G4: 2028E | H4: 2029E | I4: 2030E | K4: Notes / 预测逻辑
A6: Google Advertising 谷歌广告
A7: Google Search & other | B7: 175033 | C7: 198084 | D7: 224532 | E7: =D7*(1+CHOOSE(MATCH(Assumptions!$B$2,{"Base","Bull","Bear"},0),Assumptions!F$27,Assumptions!F$35,Assumptions!F$43)) -> 251475.84 | F7: =E7*(1+CHOOSE(MATCH(Assumptions!$B$2,{"Base","Bull","Bear"},0),Assumptions!G$27,Assumptions!G$35,Assumptions!G$43)) -> 276623.42 | G7: =F7*(1+CHOOSE(MATCH(Assumptions!$B$2,{"Base","Bull","Bear"},0),Assumptions!H$27,Assumptions!H$35,Assumptions!H$43)) -> 301519.53 | H7: =G7*(1+CHOOSE(MATCH(Assumptions!$B$2,{"Base","Bull","Bear"},0),Assumptions!I$27,Assumptions!I$35,Assumptions!I$43)) -> 325641.09 | I7: =H7*(1+CHOOSE(MATCH(Assumptions!$B$2,{"Base","Bull","Bear"},0),Assumptions!J$27,Assumptions!J$35,Assumptions!J$43)) -> 348435.97 | K7: 搜索广告核心收入，AI Overview推动
A8: yoy % | C8: =C7/B7-1 -> 0.13169517 | D8: =D7/C7-1 -> 0.13351911 | E8: =E7/D7-1 -> 0.12 | F8: =F7/E7-1 -> 0.1 | G8: =G7/F7-1 -> 0.09 | H8: =H7/G7-1 -> 0.08 | I8: =I7/H7-1 -> 0.07
A9: YouTube ads | B9: 31510 | C9: 36147 | D9: 40367 | E9: =D9*(1+CHOOSE(MATCH(Assumptions!$B$2,{"Base","Bull","Bear"},0),Assumptions!F$28,Assumptions!F$36,Assumptions!F$44)) -> 46018.38 | F9: =E9*(1+CHOOSE(MATCH(Assumptions!$B$2,{"Base","Bull","Bear"},0),Assumptions!G$28,Assumptions!G$36,Assumptions!G$44)) -> 51540.586 | G9: =F9*(1+CHOOSE(MATCH(Assumptions!$B$2,{"Base","Bull","Bear"},0),Assumptions!H$28,Assumptions!H$36,Assumptions!H$44)) -> 56694.644 | H9: =G9*(1+CHOOSE(MATCH(Assumptions!$B$2,{"Base","Bull","Bear"},0),Assumptions!I$28,Assumptions!I$36,Assumptions!I$44)) -> 61797.162 | I9: =H9*(1+CHOOSE(MATCH(Assumptions!$B$2,{"Base","Bull","Bear"},0),Assumptions!J$28,Assumptions!J$36,Assumptions!J$44)) -> 66740.935 | K9: Shorts变现+Connected TV增长
A10: yoy % | C10: =C9/B9-1 -> 0.14715963 | D10: =D9/C9-1 -> 0.11674551 | E10: =E9/D9-1 -> 0.14 | F10: =F9/E9-1 -> 0.12 | G10: =G9/F9-1 -> 0.1 | H10: =H9/G9-1 -> 0.09 | I10: =I9/H9-1 -> 0.08
A11: Google Network | B11: 31312 | C11: 30359 | D11: 29792 | E11: =D11*(1+CHOOSE(MATCH(Assumptions!$B$2,{"Base","Bull","Bear"},0),Assumptions!F$29,Assumptions!F$37,Assumptions!F$45)) -> 29196.16 | F11: =E11*(1+CHOOSE(MATCH(Assumptions!$B$2,{"Base","Bull","Bear"},0),Assumptions!G$29,Assumptions!G$37,Assumptions!G$45)) -> 28612.237 | G11: =F11*(1+CHOOSE(MATCH(Assumptions!$B$2,{"Base","Bull","Bear"},0),Assumptions!H$29,Assumptions!H$37,Assumptions!H$45)) -> 28326.114 | H11: =G11*(1+CHOOSE(MATCH(Assumptions!$B$2,{"Base","Bull","Bear"},0),Assumptions!I$29,Assumptions!I$37,Assumptions!I$45)) -> 28042.853 | I11: =H11*(1+CHOOSE(MATCH(Assumptions!$B$2,{"Base","Bull","Bear"},0),Assumptions!J$29,Assumptions!J$37,Assumptions!J$45)) -> 28042.853 | K11: 持续萎缩，向自有平台转移
A12: yoy % | C12: =C11/B11-1 -> -0.030435616 | D12: =D11/C11-1 -> -0.018676504 | E12: =E11/D11-1 -> -0.02 | F12: =F11/E11-1 -> -0.02 | G12: =G11/F11-1 -> -0.01 | H12: =H11/G11-1 -> -0.01 | I12: =I11/H11-1 -> 0
A13: Total Google Advertising 广告合计 | B13: =B7+B9+B11 -> 237855 | C13: =C7+C9+C11 -> 264590 | D13: =D7+D9+D11 -> 294691 | E13: =E7+E9+E11 -> 326690.38 | F13: =F7+F9+F11 -> 356776.25 | G13: =G7+G9+G11 -> 386540.29 | H13: =H7+H9+H11 -> 415481.11 | I13: =I7+I9+I11 -> 443219.76 | K13: Search+YouTube+Network
A15: Subscriptions, Platforms & Devices 订阅/平台/设备
A16: Subs, Platforms & Devices | B16: 34688 | C16: 40340 | D16: 48030 | E16: =D16*(1+CHOOSE(MATCH(Assumptions!$B$2,{"Base","Bull","Bear"},0),Assumptions!F$30,Assumptions!F$38,Assumptions!F$46)) -> 56675.4 | F16: =E16*(1+CHOOSE(MATCH(Assumptions!$B$2,{"Base","Bull","Bear"},0),Assumptions!G$30,Assumptions!G$38,Assumptions!G$46)) -> 65176.71 | G16: =F16*(1+CHOOSE(MATCH(Assumptions!$B$2,{"Base","Bull","Bear"},0),Assumptions!H$30,Assumptions!H$38,Assumptions!H$46)) -> 73649.682 | H16: =G16*(1+CHOOSE(MATCH(Assumptions!$B$2,{"Base","Bull","Bear"},0),Assumptions!I$30,Assumptions!I$38,Assumptions!I$46)) -> 81751.147 | I16: =H16*(1+CHOOSE(MATCH(Assumptions!$B$2,{"Base","Bull","Bear"},0),Assumptions!J$30,Assumptions!J$38,Assumptions!J$46)) -> 89108.751 | K16: YouTube Premium/Music + Pixel设备
A17: yoy % | C17: =C16/B16-1 -> 0.16293819 | D17: =D16/C16-1 -> 0.19062965 | E17: =E16/D16-1 -> 0.18 | F17: =F16/E16-1 -> 0.15 | G17: =G16/F16-1 -> 0.13 | H17: =H16/G16-1 -> 0.11 | I17: =I16/H16-1 -> 0.09
A19: Google Services Total 谷歌服务合计 | B19: =B13+B16 -> 272543 | C19: =C13+C16 -> 304930 | D19: =D13+D16 -> 342721 | E19: =E13+E16 -> 383365.78 | F19: =F13+F16 -> 421952.96 | G19: =G13+G16 -> 460189.97 | H19: =H13+H16 -> 497232.26 | I19: =I13+I16 -> 532328.51 | K19: 广告合计+订阅/平台/设备
A21: Google Cloud 谷歌云
A22: Google Cloud | B22: 33088 | C22: 43229 | D22: 58705 | E22: =D22*(1+CHOOSE(MATCH(Assumptions!$B$2,{"Base","Bull","Bear"},0),Assumptions!F$31,Assumptions!F$39,Assumptions!F$47)) -> 76316.5 | F22: =E22*(1+CHOOSE(MATCH(Assumptions!$B$2,{"Base","Bull","Bear"},0),Assumptions!G$31,Assumptions!G$39,Assumptions!G$47)) -> 95395.625 | G22: =F22*(1+CHOOSE(MATCH(Assumptions!$B$2,{"Base","Bull","Bear"},0),Assumptions!H$31,Assumptions!H$39,Assumptions!H$47)) -> 116382.66 | H22: =G22*(1+CHOOSE(MATCH(Assumptions!$B$2,{"Base","Bull","Bear"},0),Assumptions!I$31,Assumptions!I$39,Assumptions!I$47)) -> 137331.54 | I22: =H22*(1+CHOOSE(MATCH(Assumptions!$B$2,{"Base","Bull","Bear"},0),Assumptions!J$31,Assumptions!J$39,Assumptions!J$47)) -> 157931.27 | K22: GCP+Workspace，AI Cloud核心增长引擎
A23: yoy % | C23: =C22/B22-1 -> 0.30648574 | D23: =D22/C22-1 -> 0.35800042 | E23: =E22/D22-1 -> 0.3 | F23: =F22/E22-1 -> 0.25 | G23: =G22/F22-1 -> 0.22 | H23: =H22/G22-1 -> 0.18 | I23: =I22/H22-1 -> 0.15
A25: Other Bets 其他创新业务
A26: Other Bets | B26: 1527 | C26: 1648 | D26: 1537 | E26: =D26*(1+CHOOSE(MATCH(Assumptions!$B$2,{"Base","Bull","Bear"},0),Assumptions!F$32,Assumptions!F$40,Assumptions!F$48)) -> 1690.7 | F26: =E26*(1+CHOOSE(MATCH(Assumptions!$B$2,{"Base","Bull","Bear"},0),Assumptions!G$32,Assumptions!G$40,Assumptions!G$48)) -> 1944.305 | G26: =F26*(1+CHOOSE(MATCH(Assumptions!$B$2,{"Base","Bull","Bear"},0),Assumptions!H$32,Assumptions!H$40,Assumptions!H$48)) -> 2235.9507 | H26: =G26*(1+CHOOSE(MATCH(Assumptions!$B$2,{"Base","Bull","Bear"},0),Assumptions!I$32,Assumptions!I$40,Assumptions!I$48)) -> 2571.3434 | I26: =H26*(1+CHOOSE(MATCH(Assumptions!$B$2,{"Base","Bull","Bear"},0),Assumptions!J$32,Assumptions!J$40,Assumptions!J$48)) -> 2828.4777 | K26: Waymo/Verily等前沿业务
A27: yoy % | C27: =C26/B26-1 -> 0.079240341 | D27: =D26/C26-1 -> -0.067354369 | E27: =E26/D26-1 -> 0.1 | F27: =F26/E26-1 -> 0.15 | G27: =G26/F26-1 -> 0.15 | H27: =H26/G26-1 -> 0.15 | I27: =I26/H26-1 -> 0.1
A29: Hedging gains (losses) 外汇对冲 | B29: 236 | C29: 211 | D29: -127 | E29: 0 | F29: 0 | G29: 0 | H29: 0 | I29: 0 | K29: 假设为零 Assume zero
A31: Total Revenue 总收入 | B31: =B19+B22+B26+B29 -> 307394 | C31: =C19+C22+C26+C29 -> 350018 | D31: =D19+D22+D26+D29 -> 402836 | E31: =E19+E22+E26+E29 -> 461372.98 | F31: =F19+F22+F26+F29 -> 519292.89 | G31: =G19+G22+G26+G29 -> 578808.59 | H31: =H19+H22+H26+H29 -> 637135.14 | I31: =I19+I22+I26+I29 -> 693088.26 | K31: Services+Cloud+OtherBets+Hedging
A32: yoy % | C32: =C31/B31-1 -> 0.13866243 | D32: =D31/C31-1 -> 0.15090081 | E32: =E31/D31-1 -> 0.14531219 | F32: =F31/E31-1 -> 0.12553814 | G32: =G31/F31-1 -> 0.11460912 | H32: =H31/G31-1 -> 0.10077003 | I32: =I31/H31-1 -> 0.087819859
A34: Revenue Mix % 收入结构
A35: Google Search & other | B35: =B7/B31 -> 0.56940929 | C35: =C7/C31 -> 0.56592518 | D35: =D7/D31 -> 0.55737819 | E35: =E7/E31 -> 0.54505975 | F35: =F7/F31 -> 0.5326925 | G35: =G7/G31 -> 0.52093134 | H35: =H7/H31 -> 0.51110208 | I35: =I7/I31 -> 0.50272958
A36: YouTube ads | B36: =B9/B31 -> 0.10250688 | C36: =C9/C31 -> 0.10327183 | D36: =D9/D31 -> 0.10020703 | E36: =E9/E31 -> 0.099742252 | F36: =F9/F31 -> 0.099251476 | G36: =G9/G31 -> 0.097950593 | H36: =H9/H31 -> 0.096992236 | I36: =I9/I31 -> 0.096295001
A37: Google Network | B37: =B11/B31 -> 0.10186276 | C37: =C11/C31 -> 0.086735539 | D37: =D11/D31 -> 0.073955654 | E37: =E11/E31 -> 0.063281036 | F37: =F11/F31 -> 0.055098457 | G37: =G11/G31 -> 0.048938656 | H37: =H11/H31 -> 0.04401398 | I37: =I11/I31 -> 0.040460725
A38: Subs, Platforms & Devices | B38: =B16/B31 -> 0.1128454 | C38: =C16/C31 -> 0.11525122 | D38: =D16/D31 -> 0.11922966 | E38: =E16/E31 -> 0.12284074 | F38: =F16/F31 -> 0.1255105 | G38: =G16/G31 -> 0.12724359 | H38: =H16/H31 -> 0.12831053 | I38: =I16/I31 -> 0.12856768
A39: Google Cloud | B39: =B22/B31 -> 0.10764036 | C39: =C22/C31 -> 0.12350508 | D39: =D22/D31 -> 0.14572928 | E39: =E22/E31 -> 0.16541172 | F39: =F22/F31 -> 0.18370293 | G39: =G22/G31 -> 0.2010728 | H39: =H22/H31 -> 0.21554539 | I39: =I22/I31 -> 0.22786603
A40: Other Bets | B40: =B26/B31 -> 0.0049675661 | C40: =C26/C31 -> 0.0047083293 | D40: =D26/D31 -> 0.0038154485 | E40: =E26/E31 -> 0.0036644972 | F40: =F26/F31 -> 0.0037441395 | G40: =G26/G31 -> 0.0038630228 | H40: =H26/H31 -> 0.0040357896 | I40: =I26/I31 -> 0.0040809776
A43: 数据图例 Data Legend:
A44: 蓝色字体 Blue Font = 财报原始数据 Hardcoded from financials
A45: 绿色字体 Green Font = 链接自其他工作表 Links from other sheets
A46: 蓝底深蓝字体 Blue Fill = 可编辑假设 Editable assumption inputs
A47: 黄底粗体 Yellow Fill = 关键输出 Key output rows
A48: 黑色字体 Black Font = 公式计算 Calculated from formulas
A50: 数据来源 Data Sources:
A51: • Alphabet 2025 10-K Annual Report (filed Feb 4, 2026) - Consolidated Financial Statements pp.48-52
A52: • Alphabet 2025 10-K Note 15: Segment Information (Google Services, Cloud, Other Bets)
...

Sheet Segment_PL
A1: Segment P&L 分部利润表 (USD mm)
A2: Revenue / Costs / Operating Income by Division
B3: 2023 | C3: 2024 | D3: 2025 | E3: 2026E | F3: 2027E | G3: 2028E | H3: 2029E | I3: 2030E | K3: Notes / 预测逻辑
A5: Google Services 谷歌服务
A6: Revenue 收入 | B6: =Segment_Revenue!B19 -> 272543 | C6: =Segment_Revenue!C19 -> 304930 | D6: =Segment_Revenue!D19 -> 342721 | E6: =Segment_Revenue!E19 -> 383365.78 | F6: =Segment_Revenue!F19 -> 421952.96 | G6: =Segment_Revenue!G19 -> 460189.97 | H6: =Segment_Revenue!H19 -> 497232.26 | I6: =Segment_Revenue!I19 -> 532328.51 | K6: 链接自Segment_Revenue
A7: (-) Employee Comp 员工薪酬 | B7: 46224 | C7: 44560 | D7: 45124 | E7: =E6*Assumptions!$I$52 -> 49070.82 | F7: =F6*Assumptions!$I$52 -> 54009.978 | G7: =G6*Assumptions!$I$52 -> 58904.317 | H7: =H6*Assumptions!$I$52 -> 63645.729 | I7: =I6*Assumptions!$I$52 -> 68138.049 | K7: Revenue×Emp Comp%, 含SBC+福利 (Note 15)
A8: (-) Other Costs 其他费用 | B8: 130461 | C8: 139107 | D8: 158193 | E8: =E6*Assumptions!$I$53 -> 174431.43 | F8: =F6*Assumptions!$I$53 -> 191988.6 | G8: =G6*Assumptions!$I$53 -> 209386.44 | H8: =H6*Assumptions!$I$53 -> 226240.68 | I8: =I6*Assumptions!$I$53 -> 242209.47 | K8: 含TAC/内容采购/基础设施/设备成本
A9: Total Costs 总成本 | B9: =B7+B8 -> 176685 | C9: =C7+C8 -> 183667 | D9: =D7+D8 -> 203317 | E9: =E7+E8 -> 223502.25 | F9: =F7+F8 -> 245998.57 | G9: =G7+G8 -> 268290.75 | H9: =H7+H8 -> 289886.41 | I9: =I7+I8 -> 310347.52
A10: Operating Income 经营利润 | B10: =B6-B9 -> 95858 | C10: =C6-C9 -> 121263 | D10: =D6-D9 -> 139404 | E10: =E6-E9 -> 159863.53 | F10: =F6-F9 -> 175954.38 | G10: =G6-G9 -> 191899.22 | H10: =H6-H9 -> 207345.85 | I10: =I6-I9 -> 221980.99 | K10: Revenue-Total Costs
A11: Op Margin 经营利润率 | B11: =B10/B6 -> 0.35171698 | C11: =C10/C6 -> 0.39767488 | D11: =D10/D6 -> 0.40675652 | E11: =E10/E6 -> 0.417 | F11: =F10/F6 -> 0.417 | G11: =G10/G6 -> 0.417 | H11: =H10/H6 -> 0.417 | I11: =I10/I6 -> 0.417
A13: Google Cloud 谷歌云
A14: Revenue 收入 | B14: =Segment_Revenue!B22 -> 33088 | C14: =Segment_Revenue!C22 -> 43229 | D14: =Segment_Revenue!D22 -> 58705 | E14: =Segment_Revenue!E22 -> 76316.5 | F14: =Segment_Revenue!F22 -> 95395.625 | G14: =Segment_Revenue!G22 -> 116382.66 | H14: =Segment_Revenue!H22 -> 137331.54 | I14: =Segment_Revenue!I22 -> 157931.27 | K14: 链接自Segment_Revenue
A15: (-) Employee Comp 员工薪酬 | B15: 19054 | C15: 20519 | D15: 22078 | E15: =E14*Assumptions!$I$54 -> 25947.61 | F15: =F14*Assumptions!$I$54 -> 32434.513 | G15: =G14*Assumptions!$I$54 -> 39570.105 | H15: =H14*Assumptions!$I$54 -> 46692.724 | I15: =I14*Assumptions!$I$54 -> 53696.633 | K15: Revenue×Cloud Emp%, 人效持续改善
A16: (-) Other Costs 其他费用 | B16: 12318 | C16: 16598 | D16: 22717 | E16: =E14*Assumptions!$I$55 -> 29000.27 | F16: =F14*Assumptions!$I$55 -> 36250.338 | G16: =G14*Assumptions!$I$55 -> 44225.412 | H16: =H14*Assumptions!$I$55 -> 52185.986 | I16: =I14*Assumptions!$I$55 -> 60013.884 | K16: 含基础设施/第三方服务费
A17: Total Costs 总成本 | B17: =B15+B16 -> 31372 | C17: =C15+C16 -> 37117 | D17: =D15+D16 -> 44795 | E17: =E15+E16 -> 54947.88 | F17: =F15+F16 -> 68684.85 | G17: =G15+G16 -> 83795.517 | H17: =H15+H16 -> 98878.71 | I17: =I15+I16 -> 113710.52
A18: Operating Income 经营利润 | B18: =B14-B17 -> 1716 | C18: =C14-C17 -> 6112 | D18: =D14-D17 -> 13910 | E18: =E14-E17 -> 21368.62 | F18: =F14-F17 -> 26710.775 | G18: =G14-G17 -> 32587.145 | H18: =H14-H17 -> 38452.832 | I18: =I14-I17 -> 44220.756 | K18: Cloud利润率快速提升
A19: Op Margin 经营利润率 | B19: =B18/B14 -> 0.051861702 | C19: =C18/C14 -> 0.14138657 | D19: =D18/D14 -> 0.23694745 | E19: =E18/E14 -> 0.28 | F19: =F18/F14 -> 0.28 | G19: =G18/G14 -> 0.28 | H19: =H18/H14 -> 0.28 | I19: =I18/I14 -> 0.28
A21: Other Bets 其他创新业务
A22: Revenue 收入 | B22: =Segment_Revenue!B26 -> 1527 | C22: =Segment_Revenue!C26 -> 1648 | D22: =Segment_Revenue!D26 -> 1537 | E22: =Segment_Revenue!E26 -> 1690.7 | F22: =Segment_Revenue!F26 -> 1944.305 | G22: =Segment_Revenue!G26 -> 2235.9507 | H22: =Segment_Revenue!H26 -> 2571.3434 | I22: =Segment_Revenue!I26 -> 2828.4777
A23: Operating Income (Loss) 经营利润(亏损) | B23: -4095 | C23: -4444 | D23: -7515 | E23: =E22*Assumptions!$I$56 -> -5917.45 | F23: =F22*Assumptions!$I$56 -> -6805.0675 | G23: =G22*Assumptions!$I$56 -> -7825.8276 | H23: =H22*Assumptions!$I$56 -> -8999.7018 | I23: =I22*Assumptions!$I$56 -> -9899.6719 | K23: Revenue×OI Margin%, 前沿业务持续亏损
A24: Implied Costs 隐含成本 (=Rev-OI) | B24: =B22-B23 -> 5622 | C24: =C22-C23 -> 6092 | D24: =D22-D23 -> 9052 | E24: =E22-E23 -> 7608.15 | F24: =F22-F23 -> 8749.3725 | G24: =G22-G23 -> 10061.778 | H24: =H22-H23 -> 11571.045 | I24: =I22-I23 -> 12728.15
A25: Op Margin | B25: =B23/B22 -> -2.6817289 | C25: =C23/C22 -> -2.6966019 | D25: =D23/D22 -> -4.8893949 | E25: =E23/E22 -> -3.5 | F25: =F23/F22 -> -3.5 | G25: =G23/G22 -> -3.5 | H25: =H23/H22 -> -3.5 | I25: =I23/I22 -> -3.5
A27: Alphabet-level 未分配(AI研发+企业费用)
A28: Unallocated Costs 未分配费用 | B28: -9186 | C28: -10541 | D28: -16760 | E28: =-Assumptions!$I$57 -> -18000 | F28: =-Assumptions!$I$57 -> -18000 | G28: =-Assumptions!$I$57 -> -18000 | H28: =-Assumptions!$I$57 -> -18000 | I28: =-Assumptions!$I$57 -> -18000 | K28: 未分配AI研发+企业管理费用
A29: % of Total Revenue | B29: =B28/Segment_Revenue!B31 -> -0.029883472 | C29: =C28/Segment_Revenue!C31 -> -0.030115594 | D29: =D28/Segment_Revenue!D31 -> -0.04160502 | E29: =E28/Segment_Revenue!E31 -> -0.039013988 | F29: =F28/Segment_Revenue!F31 -> -0.03466252 | G29: =G28/Segment_Revenue!G31 -> -0.031098364 | H29: =H28/Segment_Revenue!H31 -> -0.028251463 | I29: =I28/Segment_Revenue!I31 -> -0.025970718
A31: Cross-Check 交叉验证: Sum of Segment OI vs Consolidated EBIT
A32: Sum of Segment OI 分部OI汇总 | B32: =B10+B18+B23+B28 -> 84293 | C32: =C10+C18+C23+C28 -> 112390 | D32: =D10+D18+D23+D28 -> 129039 | E32: =E10+E18+E23+E28 -> 157314.7 | F32: =F10+F18+F23+F28 -> 177860.09 | G32: =G10+G18+G23+G28 -> 198660.54 | H32: =H10+H18+H23+H28 -> 218798.98 | I32: =I10+I18+I23+I28 -> 238302.07 | K32: Services+Cloud+OtherBets+Alphabet-level
A33: Consolidated EBIT (from Consolidated_PL) | B33: =Consolidated_PL!B26 -> 84293 | C33: =Consolidated_PL!C26 -> 112390 | D33: =Consolidated_PL!D26 -> 129039 | E33: =Consolidated_PL!E26 -> 157314.7 | F33: =Consolidated_PL!F26 -> 177860.09 | G33: =Consolidated_PL!G26 -> 198660.54 | H33: =Consolidated_PL!H26 -> 218798.98 | I33: =Consolidated_PL!I26 -> 238302.07
A34: Difference 差异 (should = 0) | B34: =B32-B33 -> 0 | C34: =C32-C33 -> 0 | D34: =D32-D33 -> 0 | E34: =E32-E33 -> 0 | F34: =F32-F33 -> 0 | G34: =G32-G33 -> 0 | H34: =H32-H33 -> 0 | I34: =I32-I33 -> 0 | K34: 应为0，否则分部与合并口径不一致
A37: 数据图例 Data Legend:
A38: 蓝色字体 Blue Font = 财报原始数据 Hardcoded from financials
A39: 绿色字体 Green Font = 链接自其他工作表 Links from other sheets
A40: 蓝底深蓝字体 Blue Fill = 可编辑假设 Editable assumption inputs
A41: 黄底粗体 Yellow Fill = 关键输出 Key output rows
A42: 黑色字体 Black Font = 公式计算 Calculated from formulas
A44: 数据来源 Data Sources:
A45: • Alphabet 2025 10-K Annual Report (filed Feb 4, 2026) - Consolidated Financial Statements pp.48-52
A46: • Alphabet 2025 10-K Note 15: Segment Information (Google Services, Cloud, Other Bets)
A47: • Q4 2025 Earnings Call (Feb 4, 2026): CapEx 2026 guidance $75B (single quarter) → annualized ~$180B
A48: • 10Y UST yield ~4.2% (Feb 2026), Fed 2% long-term inflation target

Sheet Consolidated_PL
A1: Consolidated Income Statement 合并利润表 (USD mm)
A2: Source: 10-K p.49
B3: 2023 | C3: 2024 | D3: 2025 | E3: 2026E | F3: 2027E | G3: 2028E | H3: 2029E | I3: 2030E | K3: Notes / 预测逻辑
A5: Total Revenue 总收入 | B5: =Segment_Revenue!B31 -> 307394 | C5: =Segment_Revenue!C31 -> 350018 | D5: =Segment_Revenue!D31 -> 402836 | E5: =Segment_Revenue!E31 -> 461372.98 | F5: =Segment_Revenue!F31 -> 519292.89 | G5: =Segment_Revenue!G31 -> 578808.59 | H5: =Segment_Revenue!H31 -> 637135.14 | I5: =Segment_Revenue!I31 -> 693088.26 | K5: 链接自Segment_Revenue
A6: yoy % | C6: =C5/B5-1 -> 0.13866243 | D6: =D5/C5-1 -> 0.15090081 | E6: =E5/D5-1 -> 0.14531219 | F6: =F5/E5-1 -> 0.12553814 | G6: =G5/F5-1 -> 0.11460912 | H6: =H5/G5-1 -> 0.10077003 | I6: =I5/H5-1 -> 0.087819859
A7: Google Advertising Rev (memo) 广告收入 | B7: =Segment_Revenue!B13 -> 237855 | C7: =Segment_Revenue!C13 -> 264590 | D7: =Segment_Revenue!D13 -> 294691 | E7: =Segment_Revenue!E13 -> 326690.38 | F7: =Segment_Revenue!F13 -> 356776.25 | G7: =Segment_Revenue!G13 -> 386540.29 | H7: =Segment_Revenue!H13 -> 415481.11 | I7: =Segment_Revenue!I13 -> 443219.76 | K7: 用于计算TAC
A9: Cost of Revenues 营业成本 (COGS)
A10: TAC 流量获取成本 | B10: 49316 | C10: 54900 | D10: 59926 | E10: =E7*Assumptions!$I$61 -> 65338.076 | F10: =F7*Assumptions!$I$61 -> 71355.249 | G10: =G7*Assumptions!$I$61 -> 77308.058 | H10: =H7*Assumptions!$I$61 -> 83096.222 | I10: =I7*Assumptions!$I$61 -> 88643.952 | K10: Ad Revenue×TAC Rate
A11: TAC rate (% of Ad Rev) | B11: =B10/B7 -> 0.2073364 | C11: =C10/C7 -> 0.20749083 | D11: =D10/D7 -> 0.20335199 | E11: =E10/E7 -> 0.2 | F11: =F10/F7 -> 0.2 | G11: =G10/G7 -> 0.2 | H11: =H10/H7 -> 0.2 | I11: =I10/I7 -> 0.2
A12: Other Cost of Revenues 其他营业成本 | B12: 84016 | C12: 91406 | D12: 102609 | E12: =E5*Assumptions!$I$62 -> 115343.25 | F12: =F5*Assumptions!$I$62 -> 129823.22 | G12: =G5*Assumptions!$I$62 -> 144702.15 | H12: =H5*Assumptions!$I$62 -> 159283.79 | I12: =I5*Assumptions!$I$62 -> 173272.07 | K12: 基础设施折旧/内容/数据中心运营
A13: Other COGS % | B13: =B12/B5 -> 0.27331698 | C13: =C12/C5 -> 0.26114657 | D13: =D12/D5 -> 0.25471656 | E13: =E12/E5 -> 0.25 | F13: =F12/F5 -> 0.25 | G13: =G12/G5 -> 0.25 | H13: =H12/H5 -> 0.25 | I13: =I12/I5 -> 0.25
A14: Total COGS 营业成本合计 | B14: =B10+B12 -> 133332 | C14: =C10+C12 -> 146306 | D14: =D10+D12 -> 162535 | E14: =E10+E12 -> 180681.32 | F14: =F10+F12 -> 201178.47 | G14: =G10+G12 -> 222010.2 | H14: =H10+H12 -> 242380.01 | I14: =I10+I12 -> 261916.02
A15: Gross Profit 毛利润 | B15: =B5-B14 -> 174062 | C15: =C5-C14 -> 203712 | D15: =D5-D14 -> 240301 | E15: =E5-E14 -> 280691.66 | F15: =F5-F14 -> 318114.42 | G15: =G5-G14 -> 356798.38 | H15: =H5-H14 -> 394755.13 | I15: =I5-I14 -> 431172.24 | K15: Revenue-COGS
A16: Gross Margin 毛利率 | B16: =B15/B5 -> 0.56625048 | C16: =C15/C5 -> 0.58200435 | D16: =D15/D5 -> 0.59652315 | E16: =E15/E5 -> 0.60838339 | F16: =F15/F5 -> 0.61259151 | G16: =G15/G5 -> 0.61643588 | H16: =H15/H5 -> 0.61957834 | I16: =I15/I5 -> 0.62210294
A18: Operating Expenses 营业费用 (OpEx)
A19: R&D 研发费用 | B19: 45427 | C19: 49326 | D19: 61087 | E19: =E5*Assumptions!$I$63 -> 66899.082 | F19: =F5*Assumptions!$I$63 -> 75297.469 | G19: =G5*Assumptions!$I$63 -> 83927.245 | H19: =H5*Assumptions!$I$63 -> 92384.596 | I19: =I5*Assumptions!$I$63 -> 100497.8 | K19: AI+Cloud持续投入，规模效应显现
A20: R&D 研发费用 % | B20: =B19/B5 -> 0.14778102 | C20: =C19/C5 -> 0.14092418 | D20: =D19/D5 -> 0.15164236 | E20: =E19/E5 -> 0.145 | F20: =F19/F5 -> 0.145 | G20: =G19/G5 -> 0.145 | H20: =H19/H5 -> 0.145 | I20: =I19/I5 -> 0.145
A21: S&M 销售与营销费用 | B21: 27917 | C21: 27808 | D21: 28693 | E21: =E5*Assumptions!$I$64 -> 31373.363 | F21: =F5*Assumptions!$I$64 -> 35311.916 | G21: =G5*Assumptions!$I$64 -> 39358.984 | H21: =H5*Assumptions!$I$64 -> 43325.19 | I21: =I5*Assumptions!$I$64 -> 47130.002 | K21: 效率提升，费率持续下降
A22: S&M 销售与营销费用 % | B22: =B21/B5 -> 0.090818298 | C22: =C21/C5 -> 0.079447343 | D22: =D21/D5 -> 0.071227497 | E22: =E21/E5 -> 0.068 | F22: =F21/F5 -> 0.068 | G22: =G21/G5 -> 0.068 | H22: =H21/H5 -> 0.068 | I22: =I21/I5 -> 0.068
A23: G&A 管理费用 (含一次性项目) | B23: 16425 | C23: 14188 | D23: 21482 | E23: =E5*Assumptions!$I$65 -> 18454.919 | F23: =F5*Assumptions!$I$65 -> 20771.715 | G23: =G5*Assumptions!$I$65 -> 23152.343 | H23: =H5*Assumptions!$I$65 -> 25485.406 | I23: =I5*Assumptions!$I$65 -> 27723.53 | K23: 2025含DOJ诉讼拨备，正常化后下降
A24: G&A 管理费用 % | B24: =B23/B5 -> 0.053433053 | C24: =C23/C5 -> 0.040535058 | D24: =D23/D5 -> 0.053326912 | E24: =E23/E5 -> 0.04 | F24: =F23/F5 -> 0.04 | G24: =G23/G5 -> 0.04 | H24: =H23/H5 -> 0.04 | I24: =I23/I5 -> 0.04
A25: Estimated Total OpEx (R&D+S&M+G&A) 营业费用合计 | B25: =B19+B21+B23 -> 89769 | C25: =C19+C21+C23 -> 91322 | D25: =D19+D21+D23 -> 111262 | E25: =E19+E21+E23 -> 116727.36 | F25: =F19+F21+F23 -> 131381.1 | G25: =G19+G21+G23 -> 146438.57 | H25: =H19+H21+H23 -> 161195.19 | I25: =I19+I21+I23 -> 175351.33 | K25: 参考性合计，EBIT由分部OI驱动
A26: EBIT 经营利润 (=Sum of Segment OI) | B26: =Segment_PL!B32 -> 84293 | C26: =Segment_PL!C32 -> 112390 | D26: =Segment_PL!D32 -> 129039 | E26: =Segment_PL!E32 -> 157314.7 | F26: =Segment_PL!F32 -> 177860.09 | G26: =Segment_PL!G32 -> 198660.54 | H26: =Segment_PL!H32 -> 218798.98 | I26: =Segment_PL!I32 -> 238302.07 | K26: 分部驱动：链接自Segment_PL汇总OI
A27: EBIT Margin 经营利润率 | B27: =B26/B5 -> 0.2742181 | C27: =C26/C5 -> 0.32109777 | D27: =D26/D5 -> 0.32032639 | E27: =E26/E5 -> 0.34097077 | F27: =F26/F5 -> 0.34250438 | G27: =G26/G5 -> 0.3432232 | H27: =H26/H5 -> 0.34341063 | I27: =I26/I5 -> 0.34382645
A28: Implied OpEx (=GP-EBIT) 隐含OpEx | B28: =B15-B26 -> 89769 | C28: =C15-C26 -> 91322 | D28: =D15-D26 -> 111262 | E28: =E15-E26 -> 123376.96 | F28: =F15-F26 -> 140254.33 | G28: =G15-G26 -> 158137.84 | H28: =H15-H26 -> 175956.15 | I28: =I15-I26 -> 192870.17
A30: OI&E 其他收入/(支出) | B30: 1424 | C30: 7425 | D30: 29787 | E30: 5000 | F30: 5500 | G30: 6000 | H30: 6500 | I30: 7000 | K30: 2025含$24B非上市证券估值收益(一次性)
A31: Pre-tax Income 税前利润 | B31: =B26+B30 -> 85717 | C31: =C26+C30 -> 119815 | D31: =D26+D30 -> 158826 | E31: =E26+E30 -> 162314.7 | F31: =F26+F30 -> 183360.09 | G31: =G26+G30 -> 204660.54 | H31: =H26+H30 -> 225298.98 | I31: =I26+I30 -> 245302.07
A32: Income Tax 所得税 | B32: 11922 | C32: 19697 | D32: 26656 | E32: =E31*Assumptions!$I$11 -> 27593.499 | F32: =F31*Assumptions!$I$11 -> 31171.215 | G32: =G31*Assumptions!$I$11 -> 34792.291 | H32: =H31*Assumptions!$I$11 -> 38300.827 | I32: =I31*Assumptions!$I$11 -> 41701.352 | K32: Pre-tax Income×ETR
A33: Net Income 净利润 | B33: =B31-B32 -> 73795 | C33: =C31-C32 -> 100118 | D33: =D31-D32 -> 132170 | E33: =E31-E32 -> 134721.2 | F33: =F31-F32 -> 152188.87 | G33: =G31-G32 -> 169868.25 | H33: =H31-H32 -> 186998.15 | I33: =I31-I32 -> 203600.72 | K33: Pre-tax - Tax
A34: Net Margin 净利率 | B34: =B33/B5 -> 0.24006649 | C34: =C33/C5 -> 0.28603672 | D34: =D33/D5 -> 0.32809878 | E34: =E33/E5 -> 0.29200063 | F34: =F33/F5 -> 0.29306944 | G34: =G33/G5 -> 0.29347914 | H34: =H33/H5 -> 0.29349841 | I34: =I33/I5 -> 0.29375872
A35: NI yoy % | C35: =C33/B33-1 -> 0.35670438 | D35: =D33/C33-1 -> 0.32014223 | E35: =E33/D33-1 -> 0.019302423 | F35: =F33/E33-1 -> 0.12965794 | G35: =G33/F33-1 -> 0.1161673 | H35: =H33/G33-1 -> 0.10084233 | I35: =I33/H33-1 -> 0.088784654
A37: D&A 折旧与摊销 (memo) | B37: 11946 | C37: 15311 | D37: 21136 | E37: =E5*Assumptions!$I$66 -> 25375.514 | F37: =F5*Assumptions!$I$66 -> 28561.109 | G37: =G5*Assumptions!$I$66 -> 31834.472 | H37: =H5*Assumptions!$I$66 -> 35042.433 | I37: =I5*Assumptions!$I$66 -> 38119.854 | K37: CapEx高增长→D&A占比上升
A38: SBC 股权激励 (memo) | B38: 22460 | C38: 22785 | D38: 24953 | E38: =E5*Assumptions!$I$67 -> 26759.633 | F38: =F5*Assumptions!$I$67 -> 30118.987 | G38: =G5*Assumptions!$I$67 -> 33570.898 | H38: =H5*Assumptions!$I$67 -> 36953.838 | I38: =I5*Assumptions!$I$67 -> 40199.119 | K38: SBC占比逐步下降
A40: Diluted Shares 稀释股数 (mm) | B40: 12722 | C40: 12447 | D40: 12230 | E40: =D40*0.98 -> 11985.4 | F40: =E40*0.98 -> 11745.692 | G40: =F40*0.98 -> 11510.778 | H40: =G40*0.98 -> 11280.563 | I40: =H40*0.98 -> 11054.951 | K40: 年回购~2%股本
A41: Diluted EPS 稀释每股收益 | B41: =B33/B40 -> 5.8005817 | C41: =C33/C40 -> 8.0435446 | D41: =D33/D40 -> 10.807032 | E41: =E33/E40 -> 11.240443 | F41: =F33/F40 -> 12.956995 | G41: =G33/G40 -> 14.757321 | H41: =H33/H40 -> 16.577024 | I41: =I33/I40 -> 18.417152 | K41: Net Income / Diluted Shares
A44: 数据图例 Data Legend:
A45: 蓝色字体 Blue Font = 财报原始数据 Hardcoded from financials
A46: 绿色字体 Green Font = 链接自其他工作表 Links from other sheets
A47: 蓝底深蓝字体 Blue Fill = 可编辑假设 Editable assumption inputs
A48: 黄底粗体 Yellow Fill = 关键输出 Key output rows
...

Sheet BS
A1: Consolidated Balance Sheet 合并资产负债表 (USD mm)
A2: Source: 10-K p.48 | 2023 estimated from prior filing
B3: 2023 | C3: 2024 | D3: 2025 | E3: 2026E | F3: 2027E | G3: 2028E | H3: 2029E | I3: 2030E | K3: Notes / 预测逻辑
A5: Current Assets 流动资产
A6: Cash & Equivalents 现金 | B6: 24048 | C6: 23466 | D6: 30708 | E6: =E40+E37-E20-E7-E9-E10 -> -49092.599 | F6: =F40+F37-F20-F7-F9-F10 -> -88144.467 | G6: =G40+G37-G20-G7-G9-G10 -> -86182.398 | H6: =H40+H37-H20-H7-H9-H10 -> -44152.686 | I6: =I40+I37-I20-I7-I9-I10 -> 31898.687 | K6: 链接自CF期末现金(forecast)
A7: Marketable Securities 有价证券 | B7: 86868 | C7: 72191 | D7: 96135 | E7: =D7*1.05 -> 100941.75 | F7: =E7*1.05 -> 105988.84 | G7: =F7*1.05 -> 111288.28 | H7: =G7*1.05 -> 116852.69 | I7: =H7*1.05 -> 122695.33 | K7: 投资组合，假设温和增长
A8: Total Cash & Securities 现金合计 | B8: 110916 | C8: 95657 | D8: 126843 | E8: =E6+E7 -> 51849.151 | F8: =F6+F7 -> 17844.37 | G8: =G6+G7 -> 25105.881 | H8: =H6+H7 -> 72700.007 | I8: =I6+I7 -> 154594.02 | K8: Cash+Securities
A9: Accounts Receivable, net 应收账款 | B9: 40300 | C9: 52340 | D9: 62886 | E9: =Consolidated_PL!E5*Assumptions!$I$84/365 -> 69521.956 | F9: =Consolidated_PL!F5*Assumptions!$I$84/365 -> 78249.613 | G9: =Consolidated_PL!G5*Assumptions!$I$84/365 -> 87217.732 | H9: =Consolidated_PL!H5*Assumptions!$I$84/365 -> 96006.665 | I9: =Consolidated_PL!I5*Assumptions!$I$84/365 -> 104437.96 | K9: Revenue×AR Days/365
A10: Other Current Assets 其他流动资产 | B10: 12200 | C10: 15714 | D10: 16309 | E10: =Consolidated_PL!E5*0.04 -> 18454.919 | F10: =Consolidated_PL!F5*0.04 -> 20771.715 | G10: =Consolidated_PL!G5*0.04 -> 23152.343 | H10: =Consolidated_PL!H5*0.04 -> 25485.406 | I10: =Consolidated_PL!I5*0.04 -> 27723.53 | K10: 预付/库存/其他
A11: Total Current Assets 流动资产合计 | B11: =B8+B9+B10 -> 163416 | C11: =C8+C9+C10 -> 163711 | D11: =D8+D9+D10 -> 206038 | E11: =E8+E9+E10 -> 139826.03 | F11: =F8+F9+F10 -> 116865.7 | G11: =G8+G9+G10 -> 135475.96 | H11: =H8+H9+H10 -> 194192.08 | I11: =I8+I9+I10 -> 286755.5
A13: Non-Current Assets 非流动资产
A14: Non-marketable Securities 非上市证券 | B14: 31008 | C14: 37982 | D14: 68687 | E14: =D14*(1+Assumptions!$I$91) -> 78990.05 | F14: =E14*(1+Assumptions!$I$91) -> 90838.557 | G14: =F14*(1+Assumptions!$I$91) -> 104464.34 | H14: =G14*(1+Assumptions!$I$91) -> 120133.99 | I14: =H14*(1+Assumptions!$I$91) -> 138154.09 | K14: 含私募股权投资
A15: Deferred Income Taxes 递延所得税 | B15: 12270 | C15: 17180 | D15: 9113 | E15: 9000 | F15: 9000 | G15: 9000 | H15: 9000 | I15: 9000
A16: PP&E, net 固定资产净值 | B16: 134345 | C16: 171036 | D16: 246597 | E16: =D16+Assumptions!$I$72-Consolidated_PL!E37 -> 401221.49 | F16: =E16+Assumptions!$I$73-Consolidated_PL!F37 -> 532660.38 | G16: =F16+Assumptions!$I$74-Consolidated_PL!G37 -> 640825.91 | H16: =G16+Assumptions!$I$75-Consolidated_PL!H37 -> 725783.47 | I16: =H16+Assumptions!$I$76-Consolidated_PL!I37 -> 792663.62 | K16: Prior+CapEx-D&A
A17: Operating Lease Assets 经营租赁 | B17: 14253 | C17: 13588 | D17: 15221 | E17: =D17*(1+Assumptions!$I$90) -> 15982.05 | F17: =E17*(1+Assumptions!$I$90) -> 16781.153 | G17: =F17*(1+Assumptions!$I$90) -> 17620.21 | H17: =G17*(1+Assumptions!$I$90) -> 18501.221 | I17: =H17*(1+Assumptions!$I$90) -> 19426.282 | K17: 办公/数据中心租赁
A18: Goodwill 商誉 | B18: 29198 | C18: 31885 | D18: 33380 | E18: =D18*1.02 -> 34047.6 | F18: =E18*1.02 -> 34728.552 | G18: =F18*1.02 -> 35423.123 | H18: =G18*1.02 -> 36131.586 | I18: =H18*1.02 -> 36854.217 | K18: 收购溢价
A19: Other Non-current 其他非流动 | B19: 16902 | C19: 14874 | D19: 16245 | E19: =D19*1.03 -> 16732.35 | F19: =E19*1.03 -> 17234.321 | G19: =F19*1.03 -> 17751.35 | H19: =G19*1.03 -> 18283.891 | I19: =H19*1.03 -> 18832.407 | K19: 无形资产/其他
A20: Total Non-Current Assets 非流动资产合计 | B20: =B14+B15+B16+B17+B18+B19 -> 237976 | C20: =C14+C15+C16+C17+C18+C19 -> 286545 | D20: =D14+D15+D16+D17+D18+D19 -> 389243 | E20: =E14+E15+E16+E17+E18+E19 -> 555973.54 | F20: =F14+F15+F16+F17+F18+F19 -> 701242.96 | G20: =G14+G15+G16+G17+G18+G19 -> 825084.93 | H20: =H14+H15+H16+H17+H18+H19 -> 927834.16 | I20: =I14+I15+I16+I17+I18+I19 -> 1014930.6
A21: TOTAL ASSETS 资产合计 | B21: =B11+B20 -> 401392 | C21: =C11+C20 -> 450256 | D21: =D11+D20 -> 595281 | E21: =E11+E20 -> 695799.56 | F21: =F11+F20 -> 818108.66 | G21: =G11+G20 -> 960560.89 | H21: =H11+H20 -> 1122026.2 | I21: =I11+I20 -> 1301686.1
A23: Current Liabilities 流动负债
A24: Accounts Payable 应付账款 | B24: 7100 | C24: 7987 | D24: 12200 | E24: =Consolidated_PL!E14*Assumptions!$I$85/365 -> 12870.45 | F24: =Consolidated_PL!F14*Assumptions!$I$85/365 -> 14330.521 | G24: =Consolidated_PL!G14*Assumptions!$I$85/365 -> 15814.426 | H24: =Consolidated_PL!H14*Assumptions!$I$85/365 -> 17265.425 | I24: =Consolidated_PL!I14*Assumptions!$I$85/365 -> 18657.031 | K24: COGS×AP Days/365
A25: Accrued Compensation 应计薪酬 | B25: 14200 | C25: 15069 | D25: 17546 | E25: =Consolidated_PL!E5*Assumptions!$I$86 -> 19839.038 | F25: =Consolidated_PL!F5*Assumptions!$I$86 -> 22329.594 | G25: =Consolidated_PL!G5*Assumptions!$I$86 -> 24888.769 | H25: =Consolidated_PL!H5*Assumptions!$I$86 -> 27396.811 | I25: =Consolidated_PL!I5*Assumptions!$I$86 -> 29802.795 | K25: Revenue×AccComp%
A26: Accrued Expenses 应计费用 | B26: 43000 | C26: 51228 | D26: 55557 | E26: =Consolidated_PL!E5*Assumptions!$I$87 -> 62285.352 | F26: =Consolidated_PL!F5*Assumptions!$I$87 -> 70104.54 | G26: =Consolidated_PL!G5*Assumptions!$I$87 -> 78139.159 | H26: =Consolidated_PL!H5*Assumptions!$I$87 -> 86013.244 | I26: =Consolidated_PL!I5*Assumptions!$I$87 -> 93566.915 | K26: Revenue×AccExp%
A27: Accrued Revenue Share 应计收入分成 | B27: 8743 | C27: 9802 | D27: 10864 | E27: =Segment_Revenue!E13*Assumptions!$I$88 -> 11760.854 | F27: =Segment_Revenue!F13*Assumptions!$I$88 -> 12843.945 | G27: =Segment_Revenue!G13*Assumptions!$I$88 -> 13915.45 | H27: =Segment_Revenue!H13*Assumptions!$I$88 -> 14957.32 | I27: =Segment_Revenue!I13*Assumptions!$I$88 -> 15955.911 | K27: Ad Revenue×RevShare%
A28: Deferred Revenue 递延收入 | B28: 3993 | C28: 5036 | D28: 6578 | E28: =D28*(1+Assumptions!$I$89) -> 7564.7 | F28: =E28*(1+Assumptions!$I$89) -> 8699.405 | G28: =F28*(1+Assumptions!$I$89) -> 10004.316 | H28: =G28*(1+Assumptions!$I$89) -> 11504.963 | I28: =H28*(1+Assumptions!$I$89) -> 13230.708 | K28: Cloud预付合同增长
A29: Total Current Liabilities 流动负债合计 | B29: =B24+B25+B26+B27+B28 -> 77036 | C29: =C24+C25+C26+C27+C28 -> 89122 | D29: =D24+D25+D26+D27+D28 -> 102745 | E29: =E24+E25+E26+E27+E28 -> 114320.39 | F29: =F24+F25+F26+F27+F28 -> 128308 | G29: =G24+G25+G26+G27+G28 -> 142762.12 | H29: =H24+H25+H26+H27+H28 -> 157137.76 | I29: =I24+I25+I26+I27+I28 -> 171213.36
A31: Non-Current Liabilities 非流动负债
A32: Long-term Debt 长期债务 | B32: 12887 | C32: 10883 | D32: 46547 | E32: =Assumptions!$I$22 -> 46547 | F32: =Assumptions!$I$22 -> 46547 | G32: =Assumptions!$I$22 -> 46547 | H32: =Assumptions!$I$22 -> 46547 | I32: =Assumptions!$I$22 -> 46547 | K32: 2025发行$65B新债
A33: Income Taxes Payable, NC 长期应交税 | B33: 8049 | C33: 8782 | D33: 9531 | E33: =D33*1.03 -> 9816.93 | F33: =E33*1.03 -> 10111.438 | G33: =F33*1.03 -> 10414.781 | H33: =G33*1.03 -> 10727.224 | I33: =H33*1.03 -> 11049.041
A34: Operating Lease Liabilities 经营租赁负债 | B34: 10989 | C34: 11691 | D34: 12744 | E34: =E17*0.84 -> 13424.922 | F34: =F17*0.84 -> 14096.168 | G34: =G17*0.84 -> 14800.977 | H34: =H17*0.84 -> 15541.025 | I34: =I17*0.84 -> 16318.077 | K34: 跟踪ROU资产
A35: Other Long-term 其他长期负债 | B35: 9052 | C35: 4694 | D35: 8449 | E35: =D35*1.05 -> 8871.45 | F35: =E35*1.05 -> 9315.0225 | G35: =F35*1.05 -> 9780.7736 | H35: =G35*1.05 -> 10269.812 | I35: =H35*1.05 -> 10783.303
A36: Total Non-Current Liabilities 非流动负债 | B36: =B32+B33+B34+B35 -> 40977 | C36: =C32+C33+C34+C35 -> 36050 | D36: =D32+D33+D34+D35 -> 77271 | E36: =E32+E33+E34+E35 -> 78660.302 | F36: =F32+F33+F34+F35 -> 80069.629 | G36: =G32+G33+G34+G35 -> 81543.531 | H36: =H32+H33+H34+H35 -> 83085.062 | I36: =I32+I33+I34+I35 -> 84697.421
A37: TOTAL LIABILITIES 负债合计 | B37: =B29+B36 -> 118013 | C37: =C29+C36 -> 125172 | D37: =D29+D36 -> 180016 | E37: =E29+E36 -> 192980.7 | F37: =F29+F36 -> 208377.63 | G37: =G29+G36 -> 224305.65 | H37: =H29+H36 -> 240222.83 | I37: =I29+I36 -> 255910.78
A39: Stockholders' Equity 股东权益
A40: Total Equity 股东权益合计 | B40: 283379 | C40: 325084 | D40: 415265 | E40: =D40+Consolidated_PL!E33-Assumptions!$I$79-Assumptions!$I$80*Consolidated_PL!E40+Consolidated_PL!E38*0.5 -> 502818.87 | F40: =E40+Consolidated_PL!F33-Assumptions!$I$79-Assumptions!$I$80*Consolidated_PL!F40+Consolidated_PL!F38*0.5 -> 609731.03 | G40: =F40+Consolidated_PL!G33-Assumptions!$I$79-Assumptions!$I$80*Consolidated_PL!G40+Consolidated_PL!G38*0.5 -> 736255.23 | H40: =G40+Consolidated_PL!H33-Assumptions!$I$79-Assumptions!$I$80*Consolidated_PL!H40+Consolidated_PL!H38*0.5 -> 881803.41 | I40: =H40+Consolidated_PL!I33-Assumptions!$I$79-Assumptions!$I$80*Consolidated_PL!I40+Consolidated_PL!I38*0.5 -> 1045775.3 | K40: Prior+NI-Buyback-Div+SBC(net)
A42: TOTAL LIABILITIES & EQUITY 负债+权益 | B42: =B37+B40 -> 401392 | C42: =C37+C40 -> 450256 | D42: =D37+D40 -> 595281 | E42: =E37+E40 -> 695799.56 | F42: =F37+F40 -> 818108.66 | G42: =G37+G40 -> 960560.89 | H42: =H37+H40 -> 1122026.2 | I42: =I37+I40 -> 1301686.1
A43: Balance Check 平衡检验 (Assets - L&E) | B43: =B21-B42 -> 0 | C43: =C21-C42 -> 0 | D43: =D21-D42 -> 0 | E43: =E21-E42 -> 0 | F43: =F21-F42 -> 0 | G43: =G21-G42 -> 0 | H43: =H21-H42 -> 0 | I43: =I21-I42 -> 0 | K43: 应为0 (Cash为plug项)
A46: 数据图例 Data Legend:
A47: 蓝色字体 Blue Font = 财报原始数据 Hardcoded from financials
A48: 绿色字体 Green Font = 链接自其他工作表 Links from other sheets
...

Sheet Cash_Flow
A1: Cash Flow Statement 现金流量表 (USD mm)
A2: Source: 10-K pp.51-52
B3: 2023 | C3: 2024 | D3: 2025 | E3: 2026E | F3: 2027E | G3: 2028E | H3: 2029E | I3: 2030E | K3: Notes / 预测逻辑
A5: Operating Activities 经营活动现金流
A6: Net Income 净利润 | B6: 73795 | C6: 100118 | D6: 132170 | E6: =Consolidated_PL!E33 -> 134721.2 | F6: =Consolidated_PL!F33 -> 152188.87 | G6: =Consolidated_PL!G33 -> 169868.25 | H6: =Consolidated_PL!H33 -> 186998.15 | I6: =Consolidated_PL!I33 -> 203600.72 | K6: 链接自Consolidated_PL
A7: (+) D&A 折旧与摊销 | B7: 11946 | C7: 15311 | D7: 21136 | E7: =Consolidated_PL!E37 -> 25375.514 | F7: =Consolidated_PL!F37 -> 28561.109 | G7: =Consolidated_PL!G37 -> 31834.472 | H7: =Consolidated_PL!H37 -> 35042.433 | I7: =Consolidated_PL!I37 -> 38119.854 | K7: 非现金项目加回
A8: (+) SBC 股权激励 | B8: 22460 | C8: 22785 | D8: 24953 | E8: =Consolidated_PL!E38 -> 26759.633 | F8: =Consolidated_PL!F38 -> 30118.987 | G8: =Consolidated_PL!G38 -> 33570.898 | H8: =Consolidated_PL!H38 -> 36953.838 | I8: =Consolidated_PL!I38 -> 40199.119 | K8: 非现金项目加回
A9: Deferred Tax 递延所得税 | B9: -7763 | C9: -5257 | D9: 8348 | E9: 0 | F9: 0 | G9: 0 | H9: 0 | I9: 0 | K9: 递延税项变动
A10: (Gain)/Loss on Securities 证券损益 | B10: 823 | C10: -2671 | D10: -24620 | E10: 0 | F10: 0 | G10: 0 | H10: 0 | I10: 0 | K10: 非现金投资损益
A11: Other Adjustments 其他调整 | B11: 4330 | C11: 3419 | D11: 2108 | E11: 0 | F11: 0 | G11: 0 | H11: 0 | I11: 0 | K11: 其他非现金项目
A12: Working Capital Changes 营运资金变动
A13: Chg in AR 应收变动 | B13: -7833 | C13: -5891 | D13: -8779 | E13: =-(BS!E9-BS!D9) -> -6635.9559 | F13: =-(BS!F9-BS!E9) -> -8727.6571 | G13: =-(BS!G9-BS!F9) -> -8968.1192 | H13: =-(BS!H9-BS!G9) -> -8788.9331 | I13: =-(BS!I9-BS!H9) -> -8431.2918 | K13: 应收增加为负
A14: Chg in Tax 应交税变动 | B14: 523 | C14: -2418 | D14: -3226 | E14: 0 | F14: 0 | G14: 0 | H14: 0 | I14: 0
A15: Chg in Other Assets 其他资产变动 | B15: -2143 | C15: -1397 | D15: -4542 | E15: 0 | F15: 0 | G15: 0 | H15: 0 | I15: 0
A16: Chg in AP 应付变动 | B16: 664 | C16: 359 | D16: 907 | E16: =BS!E24-BS!D24 -> 670.45026 | F16: =BS!F24-BS!E24 -> 1460.071 | G16: =BS!G24-BS!F24 -> 1483.9043 | H16: =BS!H24-BS!G24 -> 1450.9997 | I16: =BS!I24-BS!H24 -> 1391.6062 | K16: 应付增加为正
A17: Chg in Accrued Expenses 应计费用变动 | B17: 3937 | C17: -1161 | D17: 12939 | E17: =BS!E26-BS!D26 -> 6728.3523 | F17: =BS!F26-BS!E26 -> 7819.1874 | G17: =BS!G26-BS!F26 -> 8034.6195 | H17: =BS!H26-BS!G26 -> 7874.0851 | I17: =BS!I26-BS!H26 -> 7553.671
A18: Chg in Revenue Share 收入分成变动 | B18: 482 | C18: 1059 | D18: 899 | E18: =BS!E27-BS!D27 -> 896.85368 | F18: =BS!F27-BS!E27 -> 1083.0912 | G18: =BS!G27-BS!F27 -> 1071.5056 | H18: =BS!H27-BS!G27 -> 1041.8695 | I18: =BS!I27-BS!H27 -> 998.59139
A19: Chg in Deferred Revenue 递延收入变动 | B19: 525 | C19: 1043 | D19: 2420 | E19: =BS!E28-BS!D28 -> 986.7 | F19: =BS!F28-BS!E28 -> 1134.705 | G19: =BS!G28-BS!F28 -> 1304.9107 | H19: =BS!H28-BS!G28 -> 1500.6474 | I19: =BS!I28-BS!H28 -> 1725.7445
A20: CFO 经营活动净现金 | B20: 101746 | C20: 125299 | D20: 164713 | E20: =E6+E7+E8+E9+E10+E11+E13+E14+E15+E16+E17+E18+E19 -> 189502.75 | F20: =F6+F7+F8+F9+F10+F11+F13+F14+F15+F16+F17+F18+F19 -> 213638.37 | G20: =G6+G7+G8+G9+G10+G11+G13+G14+G15+G16+G17+G18+G19 -> 238200.44 | H20: =H6+H7+H8+H9+H10+H11+H13+H14+H15+H16+H17+H18+H19 -> 262073.09 | I20: =I6+I7+I8+I9+I10+I11+I13+I14+I15+I16+I17+I18+I19 -> 285158.02 | K20: NI+D&A+SBC+调整+WC变动
A22: Investing Activities 投资活动
A23: CapEx 资本支出 | B23: -32251 | C23: -52535 | D23: -91447 | E23: =-Assumptions!$I$72 -> -180000 | F23: =-Assumptions!$I$73 -> -160000 | G23: =-Assumptions!$I$74 -> -140000 | H23: =-Assumptions!$I$75 -> -120000 | I23: =-Assumptions!$I$76 -> -105000 | K23: 2026=$180B per mgmt guidance
A24: CapEx / Revenue | B24: =-B23/Consolidated_PL!B5 -> 0.10491747 | C24: =-C23/Consolidated_PL!C5 -> 0.15009228 | D24: =-D23/Consolidated_PL!D5 -> 0.22700801 | E24: =-E23/Consolidated_PL!E5 -> 0.39013988 | F24: =-F23/Consolidated_PL!F5 -> 0.30811129 | G24: =-G23/Consolidated_PL!G5 -> 0.24187616 | H24: =-H23/Consolidated_PL!H5 -> 0.18834309 | I24: =-I23/Consolidated_PL!I5 -> 0.15149586
A26: FCF 自由现金流 (=CFO+CapEx) | B26: =B20+B23 -> 69495 | C26: =C20+C23 -> 72764 | D26: =D20+D23 -> 73266 | E26: =E20+E23 -> 9502.7483 | F26: =F20+F23 -> 53638.369 | G26: =G20+G23 -> 98200.437 | H26: =H20+H23 -> 142073.09 | I26: =I20+I23 -> 180158.02 | K26: CFO-|CapEx|
A27: FCF Margin 自由现金流利率 | B27: =B26/Consolidated_PL!B5 -> 0.22607793 | C27: =C26/Consolidated_PL!C5 -> 0.20788645 | D27: =D26/Consolidated_PL!D5 -> 0.1818755 | E27: =E26/Consolidated_PL!E5 -> 0.020596673 | F27: =F26/Consolidated_PL!F5 -> 0.10329117 | G27: =G26/Consolidated_PL!G5 -> 0.16965961 | H27: =H26/Consolidated_PL!H5 -> 0.22298738 | I27: =I26/Consolidated_PL!I5 -> 0.25993517
A29: Financing Activities 融资活动
A30: Share Repurchases 股份回购 | B30: -61504 | C30: -62222 | D30: -45709 | E30: =-Assumptions!$I$79 -> -50000 | F30: =-Assumptions!$I$79 -> -50000 | G30: =-Assumptions!$I$79 -> -50000 | H30: =-Assumptions!$I$79 -> -50000 | I30: =-Assumptions!$I$79 -> -50000 | K30: 链接自Assumptions回购假设
A31: Dividends Paid 股息支付 | B31: 0 | C31: -7363 | D31: -10049 | E31: =-Assumptions!$I$80*Consolidated_PL!E40 -> -10547.152 | F31: =-Assumptions!$I$80*Consolidated_PL!F40 -> -10336.209 | G31: =-Assumptions!$I$80*Consolidated_PL!G40 -> -10129.485 | H31: =-Assumptions!$I$80*Consolidated_PL!H40 -> -9926.8951 | I31: =-Assumptions!$I$80*Consolidated_PL!I40 -> -9728.3572 | K31: DPS×Diluted Shares
A34: 数据图例 Data Legend:
A35: 蓝色字体 Blue Font = 财报原始数据 Hardcoded from financials
A36: 绿色字体 Green Font = 链接自其他工作表 Links from other sheets
A37: 蓝底深蓝字体 Blue Fill = 可编辑假设 Editable assumption inputs
A38: 黄底粗体 Yellow Fill = 关键输出 Key output rows
A39: 黑色字体 Black Font = 公式计算 Calculated from formulas
A41: 数据来源 Data Sources:
A42: • Alphabet 2025 10-K Annual Report (filed Feb 4, 2026) - Consolidated Financial Statements pp.48-52
A43: • Alphabet 2025 10-K Note 15: Segment Information (Google Services, Cloud, Other Bets)
A44: • Q4 2025 Earnings Call (Feb 4, 2026): CapEx 2026 guidance $75B (single quarter) → annualized ~$180B
A45: • 10Y UST yield ~4.2% (Feb 2026), Fed 2% long-term inflation target

Sheet DCF
A1: DCF Valuation DCF估值 (USD mm)
A2: CapEx 2026 = $180B per mgmt guidance
B4: 2026E | C4: 2027E | D4: 2028E | E4: 2029E | F4: 2030E | G4: Notes / 预测逻辑
A6: EBIT 经营利润 | B6: =Consolidated_PL!E26 -> 157314.7 | C6: =Consolidated_PL!F26 -> 177860.09 | D6: =Consolidated_PL!G26 -> 198660.54 | E6: =Consolidated_PL!H26 -> 218798.98 | F6: =Consolidated_PL!I26 -> 238302.07 | G6: 链接自Consolidated_PL
A7: (-) Tax on EBIT EBIT税负 | B7: =B6*Assumptions!$I$11 -> 26743.499 | C7: =C6*Assumptions!$I$11 -> 30236.215 | D7: =D6*Assumptions!$I$11 -> 33772.291 | E7: =E6*Assumptions!$I$11 -> 37195.827 | F7: =F6*Assumptions!$I$11 -> 40511.352
A8: NOPAT 税后净营业利润 | B8: =B6-B7 -> 130571.2 | C8: =C6-C7 -> 147623.87 | D8: =D6-D7 -> 164888.25 | E8: =E6-E7 -> 181603.15 | F8: =F6-F7 -> 197790.72 | G8: EBIT×(1-Tax Rate)
A9: (+) D&A 折旧摊销 | B9: =Consolidated_PL!E37 -> 25375.514 | C9: =Consolidated_PL!F37 -> 28561.109 | D9: =Consolidated_PL!G37 -> 31834.472 | E9: =Consolidated_PL!H37 -> 35042.433 | F9: =Consolidated_PL!I37 -> 38119.854
A10: (-) CapEx 资本支出 | B10: =Assumptions!$I$72 -> 180000 | C10: =Assumptions!$I$73 -> 160000 | D10: =Assumptions!$I$74 -> 140000 | E10: =Assumptions!$I$75 -> 120000 | F10: =Assumptions!$I$76 -> 105000 | G10: 2026=$180B management guidance
A11: (-) Change in NWC 净营运资本变动 | B11: =(Consolidated_PL!E5-Consolidated_PL!D5)*Assumptions!$I$68 -> 292.6849 | C11: =(Consolidated_PL!F5-Consolidated_PL!E5)*Assumptions!$I$68 -> 289.59953 | D11: =(Consolidated_PL!G5-Consolidated_PL!F5)*Assumptions!$I$68 -> 297.5785 | E11: =(Consolidated_PL!H5-Consolidated_PL!G5)*Assumptions!$I$68 -> 291.63278 | F11: =(Consolidated_PL!I5-Consolidated_PL!H5)*Assumptions!$I$68 -> 279.76559
A12: UFCF 无杠杆自由现金流 | B12: =B8+B9-B10-B11 -> -24345.97 | C12: =C8+C9-C10-C11 -> 15895.384 | D12: =D8+D9-D10-D11 -> 56425.139 | E12: =E8+E9-E10-E11 -> 96353.955 | F12: =F8+F9-F10-F11 -> 130630.81 | G12: NOPAT+D&A-CapEx-ΔNWC
A13: Discount Factor 折现因子 | B13: =1/(1+Assumptions!$I$18)^1 -> 0.91500927 | C13: =1/(1+Assumptions!$I$18)^2 -> 0.83724197 | D13: =1/(1+Assumptions!$I$18)^3 -> 0.76608416 | E13: =1/(1+Assumptions!$I$18)^4 -> 0.70097411 | F13: =1/(1+Assumptions!$I$18)^5 -> 0.64139781
A14: PV of UFCF UFCF现值 | B14: =B12*B13 -> -22276.788 | C14: =C12*C13 -> 13308.283 | D14: =D12*D13 -> 43226.406 | E14: =E12*E13 -> 67541.628 | F14: =F12*F13 -> 83786.316
A16: TV 终值 (Gordon Growth Model) | B16: =F12*(1+Assumptions!$I$13)/(Assumptions!$I$18-Assumptions!$I$13) -> 2139612.3 | G16: UFCF₂₀₃₀×(1+g)/(WACC-g)
A17: PV of TV 终值现值 | B17: =B16*F13 -> 1372342.7
A18: TV as % of EV TV占比 | B18: =B17/(SUM(B14:F14)+B17) -> 0.88087653
A20: Sum of PV of UFCF UFCF现值合计 | B20: =SUM(B14:F14) -> 185585.84 | G20: 5年UFCF折现合计
A21: PV of TV 终值现值 | B21: =B17 -> 1372342.7
A22: EV 企业价值 | B22: =B20+B21 -> 1557928.5 | G22: =UFCF PV + TV PV -> #NAME?
A23: (+) Cash & Securities 加回现金 | B23: =Assumptions!$I$21 -> 126843 | G23: 年末现金+有价证券
A24: (-) Total Debt 减去债务 | B24: =Assumptions!$I$22 -> 46547 | G24: 短期+长期债务
A25: Equity Value 股权价值 | B25: =B22+B23-B24 -> 1638224.5 | G25: =EV+Cash-Debt -> #NAME?
A26: Diluted Shares 稀释股数 (mm) | B26: =Assumptions!$I$23 -> 12230
A27: Implied Share Price 隐含股价 | B27: =B25/B26 -> 133.95131 | G27: =Equity Value / Shares -> #NAME?
A31: 数据图例 Data Legend:
A32: 蓝色字体 Blue Font = 财报原始数据 Hardcoded from financials
A33: 绿色字体 Green Font = 链接自其他工作表 Links from other sheets
A34: 蓝底深蓝字体 Blue Fill = 可编辑假设 Editable assumption inputs
A35: 黄底粗体 Yellow Fill = 关键输出 Key output rows
A36: 黑色字体 Black Font = 公式计算 Calculated from formulas
A38: 数据来源 Data Sources:
A39: • Alphabet 2025 10-K Annual Report (filed Feb 4, 2026) - Consolidated Financial Statements pp.48-52
A40: • Alphabet 2025 10-K Note 15: Segment Information (Google Services, Cloud, Other Bets)
A41: • Q4 2025 Earnings Call (Feb 4, 2026): CapEx 2026 guidance $75B (single quarter) → annualized ~$180B
A42: • 10Y UST yield ~4.2% (Feb 2026), Fed 2% long-term inflation target

Sheet Sensitivity
A1: Sensitivity 敏感性分析 - Implied Share Price (USD)
A2: WACC 加权平均资本成本 × g 永续增长率
A4: g \ WACC | B4: 0.075 | C4: 0.08 | D4: 0.085 | E4: 0.09 | F4: 0.095 | G4: 0.1 | H4: 0.105
A5: 0.02 | B5: =(SUM(DCF!B14:F14)+(DCF!F12*(1+$A5)/(B$4-$A5))/((1+B$4)^5)+Assumptions!$I$21-Assumptions!$I$22)/Assumptions!$I$23 -> 159.71956 | C5: =(SUM(DCF!B14:F14)+(DCF!F12*(1+$A5)/(C$4-$A5))/((1+C$4)^5)+Assumptions!$I$21-Assumptions!$I$22)/Assumptions!$I$23 -> 145.32045 | D5: =(SUM(DCF!B14:F14)+(DCF!F12*(1+$A5)/(D$4-$A5))/((1+D$4)^5)+Assumptions!$I$21-Assumptions!$I$22)/Assumptions!$I$23 -> 133.20995 | E5: =(SUM(DCF!B14:F14)+(DCF!F12*(1+$A5)/(E$4-$A5))/((1+E$4)^5)+Assumptions!$I$21-Assumptions!$I$22)/Assumptions!$I$23 -> 122.89547 | F5: =(SUM(DCF!B14:F14)+(DCF!F12*(1+$A5)/(F$4-$A5))/((1+F$4)^5)+Assumptions!$I$21-Assumptions!$I$22)/Assumptions!$I$23 -> 114.01586 | G5: =(SUM(DCF!B14:F14)+(DCF!F12*(1+$A5)/(G$4-$A5))/((1+G$4)^5)+Assumptions!$I$21-Assumptions!$I$22)/Assumptions!$I$23 -> 106.30032 | H5: =(SUM(DCF!B14:F14)+(DCF!F12*(1+$A5)/(H$4-$A5))/((1+H$4)^5)+Assumptions!$I$21-Assumptions!$I$22)/Assumptions!$I$23 -> 99.541822
A6: 0.025 | B6: =(SUM(DCF!B14:F14)+(DCF!F12*(1+$A6)/(B$4-$A6))/((1+B$4)^5)+Assumptions!$I$21-Assumptions!$I$22)/Assumptions!$I$23 -> 174.26151 | C6: =(SUM(DCF!B14:F14)+(DCF!F12*(1+$A6)/(C$4-$A6))/((1+C$4)^5)+Assumptions!$I$21-Assumptions!$I$22)/Assumptions!$I$23 -> 157.21588 | D6: =(SUM(DCF!B14:F14)+(DCF!F12*(1+$A6)/(D$4-$A6))/((1+D$4)^5)+Assumptions!$I$21-Assumptions!$I$22)/Assumptions!$I$23 -> 143.09106 | E6: =(SUM(DCF!B14:F14)+(DCF!F12*(1+$A6)/(E$4-$A6))/((1+E$4)^5)+Assumptions!$I$21-Assumptions!$I$22)/Assumptions!$I$23 -> 131.21065 | F6: =(SUM(DCF!B14:F14)+(DCF!F12*(1+$A6)/(F$4-$A6))/((1+F$4)^5)+Assumptions!$I$21-Assumptions!$I$22)/Assumptions!$I$23 -> 121.09163 | G6: =(SUM(DCF!B14:F14)+(DCF!F12*(1+$A6)/(G$4-$A6))/((1+G$4)^5)+Assumptions!$I$21-Assumptions!$I$22)/Assumptions!$I$23 -> 112.37981 | H6: =(SUM(DCF!B14:F14)+(DCF!F12*(1+$A6)/(H$4-$A6))/((1+H$4)^5)+Assumptions!$I$21-Assumptions!$I$22)/Assumptions!$I$23 -> 104.80964
A7: 0.03 | B7: =(SUM(DCF!B14:F14)+(DCF!F12*(1+$A7)/(B$4-$A7))/((1+B$4)^5)+Assumptions!$I$21-Assumptions!$I$22)/Assumptions!$I$23 -> 192.035 | C7: =(SUM(DCF!B14:F14)+(DCF!F12*(1+$A7)/(C$4-$A7))/((1+C$4)^5)+Assumptions!$I$21-Assumptions!$I$22)/Assumptions!$I$23 -> 171.4904 | D7: =(SUM(DCF!B14:F14)+(DCF!F12*(1+$A7)/(D$4-$A7))/((1+D$4)^5)+Assumptions!$I$21-Assumptions!$I$22)/Assumptions!$I$23 -> 154.76873 | E7: =(SUM(DCF!B14:F14)+(DCF!F12*(1+$A7)/(E$4-$A7))/((1+E$4)^5)+Assumptions!$I$21-Assumptions!$I$22)/Assumptions!$I$23 -> 140.9117 | F7: =(SUM(DCF!B14:F14)+(DCF!F12*(1+$A7)/(F$4-$A7))/((1+F$4)^5)+Assumptions!$I$21-Assumptions!$I$22)/Assumptions!$I$23 -> 129.25597 | G7: =(SUM(DCF!B14:F14)+(DCF!F12*(1+$A7)/(G$4-$A7))/((1+G$4)^5)+Assumptions!$I$21-Assumptions!$I$22)/Assumptions!$I$23 -> 119.3278 | H7: =(SUM(DCF!B14:F14)+(DCF!F12*(1+$A7)/(H$4-$A7))/((1+H$4)^5)+Assumptions!$I$21-Assumptions!$I$22)/Assumptions!$I$23 -> 110.77984
A8: 0.035 | B8: =(SUM(DCF!B14:F14)+(DCF!F12*(1+$A8)/(B$4-$A8))/((1+B$4)^5)+Assumptions!$I$21-Assumptions!$I$22)/Assumptions!$I$23 -> 214.25187 | C8: =(SUM(DCF!B14:F14)+(DCF!F12*(1+$A8)/(C$4-$A8))/((1+C$4)^5)+Assumptions!$I$21-Assumptions!$I$22)/Assumptions!$I$23 -> 188.93703 | D8: =(SUM(DCF!B14:F14)+(DCF!F12*(1+$A8)/(D$4-$A8))/((1+D$4)^5)+Assumptions!$I$21-Assumptions!$I$22)/Assumptions!$I$23 -> 168.78194 | E8: =(SUM(DCF!B14:F14)+(DCF!F12*(1+$A8)/(E$4-$A8))/((1+E$4)^5)+Assumptions!$I$21-Assumptions!$I$22)/Assumptions!$I$23 -> 152.37657 | F8: =(SUM(DCF!B14:F14)+(DCF!F12*(1+$A8)/(F$4-$A8))/((1+F$4)^5)+Assumptions!$I$21-Assumptions!$I$22)/Assumptions!$I$23 -> 138.78104 | G8: =(SUM(DCF!B14:F14)+(DCF!F12*(1+$A8)/(G$4-$A8))/((1+G$4)^5)+Assumptions!$I$21-Assumptions!$I$22)/Assumptions!$I$23 -> 127.34471 | H8: =(SUM(DCF!B14:F14)+(DCF!F12*(1+$A8)/(H$4-$A8))/((1+H$4)^5)+Assumptions!$I$21-Assumptions!$I$22)/Assumptions!$I$23 -> 117.60293
